I'm sorry, but an uncaught exception occurred.

While running game code:
<<<<<<< HEAD
  File "game/script.rpy", line 62, in script
    MB "Do you have the ship ready?"
Exception: Sayer 'MB' is not defined.
=======
  File "game/script.rpy", line 123, in script
    Protag-kun "The only “me” I know is myself, so-"
NameError: name 'Protag' is not defined
>>>>>>> b659eb4923d493828258d9bb972717e0faf78e4a

-- Full Traceback ------------------------------------------------------------

Full traceback:
<<<<<<< HEAD
  File "game/script.rpy", line 62, in script
    MB "Do you have the ship ready?"
  File "C:\Users\Briswagg Nation\Documents\Ren'Py\renpy-6.99.12.4-sdk\renpy\ast.py", line 593, in execute
    who = eval_who(self.who, self.who_fast)
  File "C:\Users\Briswagg Nation\Documents\Ren'Py\renpy-6.99.12.4-sdk\renpy\ast.py", line 509, in eval_who
    raise Exception("Sayer '%s' is not defined." % who.encode("utf-8"))
Exception: Sayer 'MB' is not defined.
=======
  File "game/script.rpy", line 123, in script
    Protag-kun "The only “me” I know is myself, so-"
  File "C:\Users\Seok Hee Hong\Downloads\SETUP\renpy-6.99.12.4-sdk\renpy\ast.py", line 593, in execute
    who = eval_who(self.who, self.who_fast)
  File "C:\Users\Seok Hee Hong\Downloads\SETUP\renpy-6.99.12.4-sdk\renpy\ast.py", line 513, in eval_who
    return renpy.python.py_eval(who)
  File "C:\Users\Seok Hee Hong\Downloads\SETUP\renpy-6.99.12.4-sdk\renpy\python.py", line 1749, in py_eval
    return py_eval_bytecode(code, globals, locals)
  File "C:\Users\Seok Hee Hong\Downloads\SETUP\renpy-6.99.12.4-sdk\renpy\python.py", line 1743, in py_eval_bytecode
    return eval(bytecode, globals, locals)
  File "<none>", line 1, in <module>
NameError: name 'Protag' is not defined
>>>>>>> b659eb4923d493828258d9bb972717e0faf78e4a

Windows-8-6.2.9200
Ren'Py 6.99.12.4.2187
GWC Final Project 1.0
